<?xml version="1.0" encoding="utf-8"?>
<!-- =================================================================================== -->
<!-- |    This document was autogenerated by xacro from pibot_right_arm.urdf.xacro     | -->
<!-- |    EDITING THIS FILE BY HAND IS NOT RECOMMENDED                                 | -->
<!-- =================================================================================== -->
<robot name="right_arm_assembly">
  
  <!-- World -->
  <link name="world"/>
  <!-- World fixed joint-->
  <joint name="world_fixed" type="fixed">
    <origin rpy="0 0 0" xyz="0 0 0"/>
    <parent link="world"/>
    <child link="link1"/>
  </joint>


  <!-- link 1 -->
  <link name="link1">
    <visual>
      <origin rpy="0 0 0" xyz="0 0 0"/>
      <geometry>
        <mesh filename="package://open_manipulator_7dof_description/meshes/link1.stl" scale="0.001 0.001 0.001"/>
      </geometry>
    </visual>
    <collision>
      <origin rpy="0 0 0" xyz="0 0 0"/>
      <geometry>
        <mesh filename="package://open_manipulator_7dof_description/meshes/link1.stl" scale="0.001 0.001 0.001"/>
      </geometry>
    </collision>
    <inertial>
      <origin rpy="0 0 0" xyz="0.000001 0.000000 0.060920"/>
      <mass value="0.902"/>
      <inertia ixx="1342.575E-6" ixy="0.0" ixz="0.010E-6" iyy="1345.406E-6" iyz="0.0" izz="396.860E-6"/>
    </inertial>
  </link>
  <!-- Joint 1 -->
  <joint name="joint1" type="revolute">
    <parent link="link1"/>
    <child link="link2"/>
    <origin rpy="0 0 0" xyz="0.0 0.0 0.126"/>
    <axis xyz="0 0 1"/>
    <limit effort="1000" lower="-1.57079632679" upper="1.57079632679" velocity="6.5"/>
    <dynamics damping="0.7"/>
  </joint>
  <!-- link 2 -->
  <link name="link2">
    <visual>
      <origin rpy="0 0 0" xyz="0 0 0"/>
      <geometry>
        <mesh filename="package://open_manipulator_7dof_description/meshes/link2.stl" scale="0.001 0.001 0.001"/>
      </geometry>
    </visual>
    <collision>
      <origin rpy="0 0 0" xyz="0 0 0"/>
      <geometry>
        <mesh filename="package://open_manipulator_7dof_description/meshes/link2.stl" scale="0.001 0.001 0.001"/>
      </geometry>
    </collision>
    <inertial>
      <origin rpy="0 0 0" xyz="0.000000 0.421E-3 32.021E-3"/>
      <mass value="0.985"/>
      <inertia ixx="1612.691E-6" ixy="0.0" ixz="0.0" iyy="472.943E-6" iyz="-0.4E-6" izz="1600.221E-6"/>
    </inertial>

  </link>
  <!-- Joint 2 -->
  <joint name="joint2" type="revolute">
    <parent link="link2"/>
    <child link="link3"/>
    <origin rpy="0 0 0" xyz="0.0 0.069 0.033"/>
    <axis xyz="0 1 0"/>
    <limit effort="1000" lower="-1.57079632679" upper="1.57079632679" velocity="6.5"/>
    <dynamics damping="0.7"/>
  </joint>
  <!-- link 3 -->
  <link name="link3">
    <visual>
      <origin rpy="0 0 0" xyz="0 0 0"/>
      <geometry>
        <mesh filename="package://open_manipulator_7dof_description/meshes/link3.stl" scale="0.001 0.001 0.001"/>
      </geometry>
    </visual>
    <collision>
      <origin rpy="0 0 0" xyz="0 0 0"/>
      <geometry>
        <mesh filename="package://open_manipulator_7dof_description/meshes/link3.stl" scale="0.001 0.001 0.001"/>
      </geometry>
    </collision>
    <inertial>
      <origin rpy="0 0 0" xyz="0.001E-3 -68.958E-3 120.657E-3"/>
      <mass value="0.985"/>
      <inertia ixx="4433.148E-6" ixy="0.0" ixz="-0.018E-6" iyy="3879.057E-6" iyz="9.953E-6" izz="1285.471E-6"/>
    </inertial>

  </link>
  <!-- Joint 3 -->
  <joint name="joint3" type="revolute">
    <parent link="link3"/>
    <child link="link4"/>
    <origin rpy="0 0 0" xyz="0.0 -0.069 0.195"/>
    <axis xyz="0 0 1"/>
    <limit effort="1000" lower="-1.57079632679" upper="1.57079632679" velocity="6.5"/>
    <dynamics damping="0.7"/>
  </joint>
  <!-- link 4 -->
  <link name="link4">
    <visual>
      <origin rpy="0 0 0" xyz="0 0 0"/>
      <geometry>
        <mesh filename="package://open_manipulator_7dof_description/meshes/link4.stl" scale="0.001 0.001 0.001"/>
      </geometry>
    </visual>
    <collision>
      <origin rpy="0 0 0" xyz="0 0 0"/>
      <geometry>
        <mesh filename="package://open_manipulator_7dof_description/meshes/link4.stl" scale="0.001 0.001 0.001"/>
      </geometry>
    </collision>
    <inertial>
      <origin rpy="0 0 0" xyz="21.795E-3 -1.918E-3 85.932E-3"/>
      <mass value="1.081"/>
      <inertia ixx="1662.022E-6" ixy="-14.548E-6" ixz="-271.017E-6" iyy="1232.420E-6" iyz="-0.604E-6" izz="1397.843E-6"/>
    </inertial>

  </link>
  <!-- Joint 4 -->
  <joint name="joint4" type="revolute">
    <parent link="link4"/>
    <child link="link5"/>
    <origin rpy="0 0 0" xyz="0.029998 0.05750 0.097498"/>
    <axis xyz="0 1 0"/>
    <limit effort="1000" lower="-1.57079632679" upper="1.57079632679" velocity="6.5"/>
    <dynamics damping="0.7"/>
  </joint>
  <!-- link 5 -->
  <link name="link5">
    <visual>
      <origin rpy="0 0 0" xyz="0 0 0"/>
      <geometry>
        <mesh filename="package://open_manipulator_7dof_description/meshes/link5.stl" scale="0.001 0.001 0.001"/>
      </geometry>
    </visual>
    <collision>
      <origin rpy="0 0 0" xyz="0 0 0"/>
      <geometry>
        <mesh filename="package://open_manipulator_7dof_description/meshes/link5.stl" scale="0.001 0.001 0.001"/>
      </geometry>
    </collision>
    <inertial>
      <origin rpy="0 0 0" xyz="119.819E-3 -56.958E-3 29.666E-3"/>
      <mass value="1.284"/>
      <inertia ixx="1202.512E-6" ixy="1.548E-6" ixz="-59.770E-6" iyy="4162.303E-6" iyz="0.997E-6" izz="4540.508E-6"/>
    </inertial>

  </link>
  <!-- Joint 5 -->
  <joint name="joint5" type="revolute">
    <parent link="link5"/>
    <child link="link6"/>
    <origin rpy="0 0 0" xyz="0.195 -0.05750 0.03"/>
    <axis xyz="1 0 0"/>
    <limit effort="1000" lower="-1.57079632679" upper="1.57079632679" velocity="6.5"/>
    <dynamics damping="0.7"/>
  </joint>
  <!-- link 6 -->
  <link name="link6">
    <visual>
      <origin rpy="0 0 0" xyz="0 0 0"/>
      <geometry>
        <mesh filename="package://open_manipulator_7dof_description/meshes/link6.stl" scale="0.001 0.001 0.001"/>
      </geometry>
    </visual>
    <collision>
      <origin rpy="0 0 0" xyz="0 0 0"/>
      <geometry>
        <mesh filename="package://open_manipulator_7dof_description/meshes/link6.stl" scale="0.001 0.001 0.001"/>
      </geometry>
    </collision>
    <inertial>
      <origin rpy="0 0 0" xyz="57.143E-3 -2.069E-3 0.000E-3"/>
      <mass value="0.450"/>
      <inertia ixx="305.515E-6" ixy="0.227E-6" ixz="0.0" iyy="211.744E-6" iyz="0.0" izz="390.522E-6"/>
    </inertial>

  </link>
  <!-- Joint 6 -->
  <joint name="joint6" type="revolute">
    <parent link="link6"/>
    <child link="link7"/>
    <origin rpy="0 0 0" xyz="0.063 0.045 0.0"/>
    <axis xyz="0 1 0"/>
    <limit effort="1000" lower="-1.57079632679" upper="1.57079632679" velocity="6.5"/>
    <dynamics damping="0.7"/>
  </joint>
  <!-- link 7 -->
  <link name="link7">
    <visual>
      <origin rpy="0 0 0" xyz="0 0 0"/>
      <geometry>
        <mesh filename="package://open_manipulator_7dof_description/meshes/link7.stl" scale="0.001 0.001 0.001"/>
      </geometry>
    </visual>
    <collision>
      <origin rpy="0 0 0" xyz="0 0 0"/>
      <geometry>
        <mesh filename="package://open_manipulator_7dof_description/meshes/link7.stl" scale="0.001 0.001 0.001"/>
      </geometry>
    </collision>
    <inertial>
      <origin rpy="0 0 0" xyz="69.744E-3 -45.936E-3 -0.000E-3"/>
      <mass value="0.436"/>
      <inertia ixx="194.743E-6" ixy="-22.422E-6" ixz="-0.000" iyy="415.899E-6" iyz="0.0" izz="483.314E-6"/>
    </inertial>

  </link>
  <!-- Joint 7 -->
  <joint name="joint7" type="revolute">
    <parent link="link7"/>
    <child link="end_link"/>
    <origin rpy="0 0 0" xyz="0.1230 -0.045 0.0"/>
    <axis xyz="1 0 0"/>
    <limit effort="1000" lower="-1.57079632679" upper="1.57079632679" velocity="6.5"/>
    <dynamics damping="0.7"/>
  </joint>

  <!-- end link -->
   <link name="end_link">
    <visual>
      <origin rpy="0 0 0" xyz="0.0 0.0 0.0"/>
      <geometry>
        <mesh filename="package://open_manipulator_7dof_description/meshes/end_link.stl" scale="0.001 0.001 0.001"/>
      </geometry>
      <material name="grey"/>
    </visual>
    <collision>
      <origin rpy="0 0 0" xyz="0.0 0.0 0.0"/>
      <geometry>
        <mesh filename="package://open_manipulator_7dof_description/meshes/end_link.stl" scale="0.001 0.001 0.001"/>
      </geometry>
    </collision>
    <inertial>
      <origin rpy="0 0 0" xyz="0.00337 0.00000 0.00000"/>
      <!-- <mass value="0.01919"/>
      <inertia ixx="1.0" ixy="0.0" ixz="0.0" iyy="1.0" iyz="0.0" izz="1.0"/> -->
      <!-- Fake inertial -->
      <mass value="0.0000000000000000000000000000001"/>
      <inertia ixx="0.0" iyy="0.0" izz="0.0" ixy="+0.0" iyz="+0.0" ixz="-0.0"/>
      <!--<inertia ixx="0.00000938" ixy="0.0" ixz="0.0" iyy="0.00000338" iyz="0.0" izz="0.00000635" /> -->
    </inertial>
  </link>
</robot>

