<?xml version="1.0" encoding="utf-8"?>
<!-- =================================================================================== -->
<!-- |    This document was autogenerated by xacro from pibot_upper_body.urdf.xacro    | -->
<!-- |    EDITING THIS FILE BY HAND IS NOT RECOMMENDED                                 | -->
<!-- =================================================================================== -->
<robot name="pibot_right_arm">
  <link name="world"/>
  <joint name="world_joint" type="fixed">
    <parent link="world"/>
    <child link="rightarm_link1"/>
    <origin rpy="0.0 0.0 0.0" xyz="0.0 0.0 0.0"/>
  </joint>

  <!-- link 1 -->
  <link name="rightarm_link1">
    <visual>
      <origin rpy="0 0 0" xyz="0 0 0"/>
      <geometry>
        <mesh filename="package://open_manipulator_7dof_description/meshes/link1.stl" scale="0.001 0.001 0.001"/>
      </geometry>
      <material name="rightarm_grey"/>
    </visual>
    <collision>
      <origin rpy="0 0 0" xyz="0 0 0"/>
      <geometry>
        <mesh filename="package://open_manipulator_7dof_description/meshes/link1.stl" scale="0.001 0.001 0.001"/>
      </geometry>
    </collision>
    <inertial>
      <origin rpy="0 0 0" xyz="0.001e-3 0.00e-3 60.920e-3"/>
      <mass value="0.855"/>
      <inertia ixx="1272.200e-06" ixy="0.0" ixz="0.010e-6" iyx="0.0" iyy="1274.884e-06" iyz="0.0" izx="0.010e-6" izy="0.0" izz="376.058e-06"/>
      <!-- <inertia ixx="1.2766146" ixy="1.1040986e-02" ixz="3.6647805e-02" iyy="1.2415274" iyz="-9.7595981e-02" izz="3.6863307e-01" /> -->
      <!--<inertia ixx="0.00121064" ixy="0.0" ixz="0.00001100" iyy="0.00120886" iyz="0.0" izz="0.00038103" />-->
    </inertial>
  </link>
  <!-- Joint 1 -->
  <joint name="rightarm_joint1" type="revolute">
    <parent link="rightarm_link1"/>
    <child link="rightarm_link2"/>
    <origin rpy="0 0 0" xyz="0.0 0.0 0.126"/>
    <axis xyz="0 0 1"/>
    <limit effort="1000" lower="-2.98451302091" upper="2.98451302091" velocity="6.5"/>
    <dynamics damping="0.7"/>
  </joint>
  <!-- link 2 -->
  <link name="rightarm_link2">
    <visual>
      <origin rpy="0 0 0" xyz="0 0 0"/>
      <geometry>
        <mesh filename="package://open_manipulator_7dof_description/meshes/link2.stl" scale="0.001 0.001 0.001"/>
      </geometry>
      <material name="rightarm_grey"/>
    </visual>
    <collision>
      <origin rpy="0 0 0" xyz="0 0 0"/>
      <geometry>
        <mesh filename="package://open_manipulator_7dof_description/meshes/link2.stl" scale="0.001 0.001 0.001"/>
      </geometry>
    </collision>
    <inertial>
      <origin rpy="0 0 0" xyz="0.0 0.238e-3 32.024e-3"/>
      <mass value="9.4360595e-01"/>
      <inertia ixx="1552.686e-06" ixy="0.0" ixz="0.0" iyx="0.0" iyy="453.275e-6" iyz="-0.213e-6" izx="0.0" izy="-0.213e-6" izz="1540.777e-06"/>
    </inertial>
  </link>
  <!-- Joint 2 -->
  <joint name="rightarm_joint2" type="revolute">
    <parent link="rightarm_link2"/>
    <child link="rightarm_link3"/>
    <origin rpy="0 0 0" xyz="0.0 0.069 0.033"/>
    <axis xyz="0 1 0"/>
    <limit effort="1000" lower="-1.57079632679" upper="1.57079632679" velocity="6.5"/>
    <dynamics damping="0.7"/>
  </joint>
  <!-- link 3 -->
  <link name="rightarm_link3">
    <visual>
      <origin rpy="0 0 0" xyz="0 0 0"/>
      <geometry>
        <mesh filename="package://open_manipulator_7dof_description/meshes/link3.stl" scale="0.001 0.001 0.001"/>
      </geometry>
      <material name="rightarm_grey"/>
    </visual>
    <collision>
      <origin rpy="0 0 0" xyz="0 0 0"/>
      <geometry>
        <mesh filename="package://open_manipulator_7dof_description/meshes/link3.stl" scale="0.001 0.001 0.001"/>
      </geometry>
    </collision>
    <inertial>
      <origin rpy="0 0 0" xyz="0.001e-3 -68.947e-3 116.982e-3"/>
      <!--<origin xyz="-0.01232 -0.05731 -0.05876" rpy="0 0 0"/>-->
      <mass value="1.280"/>
      <inertia ixx="4955.278e-6" ixy="0.0" ixz="-0.021e-6" iyy="4269.315e-6" iyz="11.989e-6" izz="1425.683e-6"/>
    </inertial>
  </link>
  <!-- Joint 3 -->
  <joint name="rightarm_joint3" type="revolute">
    <parent link="rightarm_link3"/>
    <child link="rightarm_link4"/>
    <origin rpy="0 0 1.57079632679" xyz="0.0 -0.069 0.195"/>
    <axis xyz="0 0 1"/>
    <limit effort="1000" lower="-2.35619449019" upper="2.35619449019" velocity="6.5"/>
    <dynamics damping="0.7"/>
  </joint>
  <!-- link 4 -->
  <link name="rightarm_link4">
    <visual>
      <origin rpy="0 0 0" xyz="0 0 0"/>
      <geometry>
        <mesh filename="package://open_manipulator_7dof_description/meshes/link4.stl" scale="0.001 0.001 0.001"/>
      </geometry>
      <material name="rightarm_grey"/>
    </visual>
    <collision>
      <origin rpy="0 0 0" xyz="0 0 0"/>
      <geometry>
        <mesh filename="package://open_manipulator_7dof_description/meshes/link4.stl" scale="0.001 0.001 0.001"/>
      </geometry>
    </collision>
    <inertial>
      <origin rpy="0 0 0" xyz="21.079e-3 -2.170e-3 84.922e-3"/>
      <!--<origin xyz="-0.07025 0.00034 -0.00021" rpy="0 0 0"/>-->
      <mass value="1.080"/>
      <inertia ixx="1681.850e-6" ixy="-13.377e-6" ixz="-284.416e-6" iyy="1276.396e-6" iyz="2.756e-6" izz="1401.788e-6"/>
      <!--<inertia ixx="0.00096726" ixy="0.00004383" ixz="-0.00002771" iyy="0.00318801" iyz="0.00000627" izz="0.00341484" />-->
    </inertial>
  </link>
  <!-- Joint 4 -->
  <joint name="rightarm_joint4" type="revolute">
    <parent link="rightarm_link4"/>
    <child link="rightarm_link5"/>
    <origin rpy="0 0 0" xyz="0.029998 0.05750 0.097498"/>
    <axis xyz="0 1 0"/>
    <limit effort="1000" lower="-2.04203522483" upper="1.57079632679" velocity="6.5"/>
    <dynamics damping="0.7"/>
  </joint>
  <!-- link 5 -->
  <link name="rightarm_link5">
    <visual>
      <origin rpy="0 0 0" xyz="0 0 0"/>
      <geometry>
        <mesh filename="package://open_manipulator_7dof_description/meshes/link5.stl" scale="0.001 0.001 0.001"/>
      </geometry>
      <material name="rightarm_grey"/>
    </visual>
    <collision>
      <origin rpy="0 0 0" xyz="0 0 0"/>
      <geometry>
        <mesh filename="package://open_manipulator_7dof_description/meshes/link5.stl" scale="0.001 0.001 0.001"/>
      </geometry>
    </collision>
    <inertial>
      <origin rpy="0 0 0" xyz="120.043e-3 -56.958e-3 29.662e-3"/>
      <mass value="1.2126965e+00"/>
      <inertia ixx="1149.216e-6" ixy="1.483e-6" ixz="-57.426e-6" iyx="1.483e-6" iyy="4036.713e-6" iyz="0.956e-6" izx="-57.426e-6" izy="0.956e-6" izz="4400.519e-6"/>
    </inertial>
  </link>
  <!-- Joint 5 -->
  <joint name="rightarm_joint5" type="revolute">
    <parent link="rightarm_link5"/>
    <child link="rightarm_link6"/>
    <origin rpy="0 0 0" xyz="0.195 -0.05750 0.03"/>
    <axis xyz="1 0 0"/>
    <limit effort="1000" lower="-2.98451302091" upper="2.98451302091" velocity="6.5"/>
    <dynamics damping="0.7"/>
  </joint>
  <!-- link 6 -->
  <link name="rightarm_link6">
    <visual>
      <origin rpy="0 0 0" xyz="0 0 0"/>
      <geometry>
        <mesh filename="package://open_manipulator_7dof_description/meshes/link6.stl" scale="0.001 0.001 0.001"/>
      </geometry>
      <material name="rightarm_grey"/>
    </visual>
    <collision>
      <origin rpy="0 0 0" xyz="0 0 0"/>
      <geometry>
        <mesh filename="package://open_manipulator_7dof_description/meshes/link6.stl" scale="0.001 0.001 0.001"/>
      </geometry>
    </collision>
    <inertial>
      <origin rpy="0 0 0" xyz="57.143e-3 -2.069e-3 0.0"/>
      <mass value="4.6635550e-01"/>
      <inertia ixx="316.833e-6" ixy="0.235e-6" ixz="0.0" iyx="0.235e-6" iyy="219.588e-6" iyz="0.0" izx="0.0" izy="0.0" izz="404.989e-6"/>
    </inertial>
  </link>
  <!-- Joint 6 -->
  <joint name="rightarm_joint6" type="revolute">
    <parent link="rightarm_link6"/>
    <child link="rightarm_link7"/>
    <origin rpy="0 0 0" xyz="0.063 0.045 0.0"/>
    <axis xyz="0 1 0"/>
    <limit effort="1000" lower="-1.57079632679" upper="1.57079632679" velocity="6.5"/>
    <dynamics damping="0.7"/>
  </joint>
  <!-- link 7 -->
  <link name="rightarm_link7">
    <visual>
      <origin rpy="0 0 0" xyz="0 0 0"/>
      <geometry>
        <mesh filename="package://open_manipulator_7dof_description/meshes/link7.stl" scale="0.001 0.001 0.001"/>
      </geometry>
      <material name="rightarm_grey"/>
    </visual>
    <collision>
      <origin rpy="0 0 0" xyz="0 0 0"/>
      <geometry>
        <mesh filename="package://open_manipulator_7dof_description/meshes/link7.stl" scale="0.001 0.001 0.001"/>
      </geometry>
    </collision>
    <inertial>
      <origin rpy="0 0 0" xyz="69.744e-3 -45.936e-3 0.0"/>
      <mass value="4.2561606e-01"/>
      <inertia ixx="190.122e-6" ixy="-21.890e-6" ixz="0.00" iyx="-21.890e-6" iyy="406.031e-6" iyz="0.00" izx="0.00" izy="0.00" izz="471.847e-6"/>
    </inertial>
  </link>
  <!-- Joint 7 -->
  <joint name="rightarm_joint7" type="revolute">
    <parent link="rightarm_link7"/>
    <child link="rightarm_fake_end_link"/>
    <origin rpy="0 0 0" xyz="0.1230 -0.045 0.0"/>
    <axis xyz="1 0 0"/>
    <limit effort="1000" lower="-2.98451302091" upper="2.98451302091" velocity="6.5"/>
    <dynamics damping="0.7"/>
  </joint>
  <!-- end link -->
  <link name="rightarm_fake_end_link">
    <visual>
      <origin rpy="0 0 0" xyz="0.0 0.0 0.0"/>
      <geometry>
        <box size="0.01 0.01 0.01"/>
      </geometry>
      <material name="rightarm_grey"/>
    </visual>
    <!-- <collision>
      <origin xyz="0.0 0.0 0.0" rpy="0 0 0" />
      <geometry>
          <box size="0.01 0.01 0.01" />
        </geometry>
    </collision> -->
    <inertial>
      <origin rpy="0 0 0" xyz="0.00337 0.00000 0.00000"/>
      <mass value="0.01919"/>
      <inertia ixx="1.0" ixy="0.0" ixz="0.0" iyy="1.0" iyz="0.0" izz="1.0"/>
      <!--<inertia ixx="0.00000938" ixy="0.0" ixz="0.0" iyy="0.00000338" iyz="0.0" izz="0.00000635" />-->
    </inertial>
  </link>

  <joint name="rightarm_to_link" type="fixed">
    <parent link="rightarm_fake_end_link"/>
    <child link="rightarm_sensor_link"/>
    <!-- TODO: check base_link name of robot -->
    <axis xyz="1 0 0"/>
    <origin rpy="-3.14159265359 0.0 0.0" xyz="0.0 0.0 0.0"/>
  </joint>

  <!-- end link -->
  <!-- <link name="end_link">
    <visual>
      <origin xyz="0.0 0.0 0.0" rpy="0 0 0" />
      <geometry>
        <mesh filename="package://open_manipulator_7dof_description/meshes/end_link.stl" scale="0.001 0.001 0.001"/>
      </geometry>
      <material name="grey"/>
    </visual>

    <collision>
      <origin xyz="0.0 0.0 0.0" rpy="0 0 0" />
      <geometry>
        <mesh filename="package://open_manipulator_7dof_description/meshes/end_link.stl" scale="0.001 0.001 0.001"/>
      </geometry>
    </collision>

    <inertial>
      <origin xyz="0.00337 0.00000 0.00000" rpy="0 0 0"/>
      <mass value="0.01919"/>
      <inertia ixx="1.0" ixy="0.0" ixz="0.0" iyy="1.0" iyz="0.0" izz="1.0" />
      <!-<inertia ixx="0.00000938" ixy="0.0" ixz="0.0" iyy="0.00000338" iyz="0.0" izz="0.00000635" />->
    </inertial>
  </link> -->
  <!-- World -->
  <!-- World fixed joint-->
  <!-- <link name="world"/>
  <joint name="world_fixed" type="fixed">
    <origin xyz="0 0 0" rpy="0 0 0"/>
    <parent link="world"/>
    <child link="link1"/>
  </joint> -->
  <!-- <link name="world" />
  <joint name="world_joint" type="fixed">
    <parent link="world" />
    <child link="base_link" />
    <origin rpy="0.0 0.0 0.0" xyz="0.0 0.0 0.0" />
  </joint> -->
  
  <!-- sensor_link -->
  <link name="rightarm_sensor_link">
    <visual>
      <origin rpy="0 0 0" xyz="0 0 0"/>
      <geometry>
        <mesh filename="package://open_manipulator_7dof_description/meshes/Arm2Hand.stl" scale="0.001 0.001 0.001"/>
      </geometry>
      <color rgba="0.5 0.5 0.5 0.5"/>
    </visual>
    <collision>
      <origin rpy="0 0 0" xyz="0 0 0"/>
      <geometry>
        <mesh filename="package://open_manipulator_7dof_description/meshes/Arm2Hand.stl" scale="0.001 0.001 0.001"/>
      </geometry>
    </collision>
    <inertial>
      <origin rpy="0 0 0" xyz="0.00000 0.00080 0.03183"/>
      <!--<origin xyz="0.00000 -0.06820 -0.00117" rpy="0 0 0"/>-->
      <mass value="0.94658"/>
      <inertia ixx="1.0" ixy="0.0" ixz="0.0" iyy="1.0" iyz="0.0" izz="1.0"/>
      <!--<inertia ixx="0.00152547" ixy="0.0" ixz="0.0" iyy="0.00045954" iyz="-0.00001086" izz="0.00151740" />-->
    </inertial>
  </link>
  <!-- camera body, with origin at bottom screw mount -->
  <joint name="rightarm_camera_joint" type="fixed">
    <origin rpy="0 0 0" xyz="0.021275 0 0.0635"/>
    <parent link="rightarm_sensor_link"/>
    <child link="rightarm_camera_bottom_screw_frame"/>
  </joint>
  <link name="rightarm_camera_bottom_screw_frame">
    <inertial>
      <origin xyz="0 0 0" rpy="0 0 0"/>
      <mass value="0.0000000000000000000000000000001"/>
      <inertia ixx="0.0" iyy="0.0" izz="0.0" ixy="+0.0" iyz="+0.0" ixz="-0.0"/>
    </inertial>
  </link>
  <joint name="rightarm_camera_link_joint" type="fixed">
    <origin rpy="0 0 0" xyz="0.0106 0.0175 0.0125"/>
    <parent link="rightarm_camera_bottom_screw_frame"/>
    <child link="rightarm_camera_link"/>
  </joint>
  <link name="rightarm_camera_link">
    <visual>
      <!-- the mesh origin is at front plate in between the two infrared camera axes -->
      <origin rpy="1.57079632679 0 1.57079632679" xyz="0.0043 -0.0175 0"/>
      <geometry>
        <mesh filename="package://realsense2_description/meshes/d435.stl"/>
      </geometry>
    </visual>
    <collision>
      <origin rpy="0 0 0" xyz="0 -0.0175 0"/>
      <geometry>
        <box size="0.02505 0.09 0.025"/>
      </geometry>
    </collision>
    <inertial>
      <!-- The following are not reliable values, and should not be used for modeling -->
      <mass value="0.072"/>
      <origin xyz="0 0 0"/>
      <inertia ixx="0.003881243" ixy="0.0" ixz="0.0" iyy="0.000498940" iyz="0.0" izz="0.003879257"/>
    </inertial>
  </link>

  <link name="end_effector">
    <tcp number="1"/>
    <inertial>
      <origin xyz="0 0 0" rpy="0 0 0"/>
      <mass value="0.0000000000000000000000000000001"/>
      <inertia ixx="0.0" iyy="0.0" izz="0.0" ixy="+0.0" iyz="+0.0" ixz="-0.0"/>
    </inertial>
  </link>

  <joint name="end_effector" type="fixed">
    <origin xyz="0.06 0 0" rpy="0 0 0" />
    <parent link="rightarm_fake_end_link" />
    <child link="end_effector" />
    <axis xyz="0 0 0" />
  </joint>
  
  
</robot>

